<?xml version="1.0" ?>
<!-- Generated using onshape-to-robot -->
<!-- Onshape document_id: 7b20e5b37bb2d82f8dd706c6 / workspace_id: 09d0d110c8b8f64040badaa0 -->
<robot name="fish_hpurv">
  <!-- Link link_base -->
  <link name="link_base">
    <inertial>
      <origin xyz="0 0 0" rpy="0 0 0"/>
      <mass value="1e-09"/>
      <inertia ixx="1e-09" ixy="0" ixz="0" iyy="1e-09" iyz="0" izz="1e-09"/>
    </inertial>
    <!-- Part link_base -->
    <visual>
      <origin xyz="0.00565115 0.012105 0.000613418" rpy="0 -0 0"/>
      <geometry>
        <mesh filename="./meshes/link_base.stl"/>
      </geometry>
      <material name="link_base_material">
        <color rgba="0.615686 0.811765 0.929412 1.0"/>
      </material>
    </visual>
    <collision>
      <origin xyz="0.00565115 0.012105 0.000613418" rpy="0 -0 0"/>
      <geometry>
        <mesh filename="./meshes/link_base.stl"/>
      </geometry>
    </collision>
  </link>
  <!-- Link link_p2 -->
  <link name="link_p2">
    <inertial>
      <origin xyz="0 0 0" rpy="0 0 0"/>
      <mass value="1e-09"/>
      <inertia ixx="1e-09" ixy="0" ixz="0" iyy="1e-09" iyz="0" izz="1e-09"/>
    </inertial>
    <!-- Part link_p2 -->
    <visual>
      <origin xyz="0 0.003 -0.0026" rpy="1.5708 1.5708 0"/>
      <geometry>
        <mesh filename="./meshes/link_p2.stl"/>
      </geometry>
      <material name="link_p2_material">
        <color rgba="0.615686 0.811765 0.929412 1.0"/>
      </material>
    </visual>
    <collision>
      <origin xyz="0 0.003 -0.0026" rpy="1.5708 1.5708 0"/>
      <geometry>
        <mesh filename="./meshes/link_p2.stl"/>
      </geometry>
    </collision>
  </link>
  <!-- Joint from link_base to link_p2 -->
  <joint name="joint1" type="revolute">
    <origin xyz="0.00565115 0.012105 0.0290034" rpy="3.14159 -0 0"/>
    <parent link="link_base"/>
    <child link="link_p2"/>
    <axis xyz="0 0 1"/>
    <limit effort="10" velocity="10" lower="-0.523599" upper="0.523599"/>
  </joint>
  <!-- Link link_p1 -->
  <link name="link_p1">
    <inertial>
      <origin xyz="0 0 0" rpy="0 0 0"/>
      <mass value="1e-09"/>
      <inertia ixx="1e-09" ixy="0" ixz="0" iyy="1e-09" iyz="0" izz="1e-09"/>
    </inertial>
    <!-- Part link_p1 -->
    <visual>
      <origin xyz="0 0.003 -0.0026" rpy="1.5708 1.5708 0"/>
      <geometry>
        <mesh filename="./meshes/link_p1.stl"/>
      </geometry>
      <material name="link_p1_material">
        <color rgba="0.615686 0.811765 0.929412 1.0"/>
      </material>
    </visual>
    <collision>
      <origin xyz="0 0.003 -0.0026" rpy="1.5708 1.5708 0"/>
      <geometry>
        <mesh filename="./meshes/link_p1.stl"/>
      </geometry>
    </collision>
  </link>
  <!-- Joint from link_base to link_p1 -->
  <joint name="joint2" type="revolute">
    <origin xyz="0.00565115 0.012105 -0.00238658" rpy="1.22465e-16 -0 0"/>
    <parent link="link_base"/>
    <child link="link_p1"/>
    <axis xyz="0 0 1"/>
    <limit effort="10" velocity="10" lower="-0.523599" upper="0.523599"/>
  </joint>
</robot>
